Workbook

Sheet Cover
A1: BESS IEX Arbitrage · Financial Model
A2: P7 Tumkur · P8 Bidar · P12 Kunnoor 4 · BESS sized from CTU night connectivity · IEX prices 2025-09-20 to 2026-09-23
A4: Sheet | B4: What it holds
A5: Assumptions | B5: Every input with units and sources. Scenario selectors at the top.
A6: Model | B6: Solar + BESS model for the selected plant, duration and charging case: sizing, prices, capex, 25-year P&L, cash flow, debt, IRR, NPV, DSCR, levelised cost.
A7: CATL 1 cycle / CATL 2 cycles | B7: CATL 12,000-cycle BESS on IEX only, one or two cycles a day, with cycle-based fade and cell replacement.
A8: Solar PPA | B8: BESS buys solar from the plant at a fixed tariff (₹2.545/kWh) and sells on DAM / GDAM / RTM or at a flexible price.
A9: Prices / SepDays / PricesMonth / SolarProfile | B9: IEX 15-minute average prices (annual, September daily, monthly) and plant solar profiles.
A10: Dispatch | B10: Own-solar daily charging results from the HTML model’s 15-minute simulation.
A11: Scenarios | B11: Reference results from the HTML model for checking.
A12: Colour legend
A13: Blue text | B13: Input you can change
A14: Yellow fill | B14: Key assumption
A15: Black text | B15: Formula
A16: Green text | B16: Link from another sheet
A18: Live results | B18: Solar + BESS | C18: CATL 1 cycle | D18: CATL 2 cycles | E18: Solar PPA
A19: Scenario | B19: =Assumptions!$B$6&" · "&Assumptions!$B$7&"h · "&Assumptions!$B$8 -> P7 · 2h · IEX + T-GNA | C19: =Assumptions!$B$6&" · "&Assumptions!$B$65&"h · "&Assumptions!$B$66 -> P7 · 4h · T-GNA | E19: =Assumptions!$B$6&" · "&Assumptions!$B$92&"h · sell "&Assumptions!$B$93 -> P7 · 2h · sell GDAM
A20: Project IRR, post-tax | B20: =Model!$C$53 -> 0.089834966 | C20: ='CATL 1 cycle'!$C$43 -> 0.067010229 | D20: ='CATL 2 cycles'!$C$47 -> -0.006736948 | E20: ='Solar PPA'!$C$68 -> 0.088750846
A21: Project IRR, pre-tax | B21: =Model!$C$54 -> 0.11653066 | C21: ='CATL 1 cycle'!$C$44 -> 0.086794874 | D21: ='CATL 2 cycles'!$C$48 -> 0.00085055545 | E21: ='Solar PPA'!$C$69 -> 0.1151783
A22: Equity IRR, post-tax | B22: =Model!$C$55 -> 0.10623429 | C22: ='CATL 1 cycle'!$C$45 -> 0.063226331 | D22: ='CATL 2 cycles'!$C$49 -> -0.058659564 | E22: ='Solar PPA'!$C$70 -> 0.10407867
A23: WACC | B23: =Model!$C$48 -> 0.09176195 | C23: ='CATL 1 cycle'!$C$38 -> 0.09176195 | D23: ='CATL 2 cycles'!$C$42 -> 0.09176195 | E23: ='Solar PPA'!$C$63 -> 0.09176195
A24: NPV at WACC, ₹ Cr | B24: =Model!$C$56 -> -10.667982 | C24: ='CATL 1 cycle'!$C$46 -> -275.87434 | D24: ='CATL 2 cycles'!$C$50 -> -905.87041 | E24: ='Solar PPA'!$C$71 -> -16.646881
A25: Payback, years | B25: =Model!$C$57 -> 9.1950373 | C25: ='CATL 1 cycle'!$C$47 -> 11.404182 | D25: ='CATL 2 cycles'!$C$51 -> beyond life | E25: ='Solar PPA'!$C$72 -> 9.2722994
A26: Minimum DSCR | B26: =Model!$C$58 -> 1.2634267 | C26: ='CATL 1 cycle'!$C$48 -> 1.0112613 | D26: ='CATL 2 cycles'!$C$52 -> 0.59156896 | E26: ='Solar PPA'!$C$73 -> 1.2548116
A27: Total capex, ₹ Cr | B27: =Model!$C$46 -> 707.96642 | C27: ='CATL 1 cycle'!$C$36 -> 1514.8073 | D27: ='CATL 2 cycles'!$C$40 -> 1521.7223 | E27: ='Solar PPA'!$C$61 -> 707.96642
A28: BESS nameplate, MWh | B28: =Model!$C$17 -> 722.41471 | C28: ='CATL 1 cycle'!$C$15 -> 1442.6736 | D28: ='CATL 2 cycles'!$C$15 -> 1449.2593 | E28: ='Solar PPA'!$C$16 -> 722.41471
A31: How the model works: the BESS is sized so the full night connectivity is exported for the whole window (2 or 4 h). Own-solar charging builds only enough solar to charge that BESS. IEX-purchase and CATL cases are fully live formulas. Own-solar daily charging (how full the battery gets each day, surplus solar) comes from the HTML model’s 15-minute simulation (Dispatch sheet) at default windows and sizing.
A36: Units: ₹ Cr = ₹ crore (10 million). Prices ₹/MWh unless shown as ₹/kWh. Percentages are stored as fractions.

Sheet Assumptions
A1: Assumptions
A2: Blue = input you can change · yellow = key assumption · black = formula · green = link from another sheet. Percentages are stored as fractions (90% = 0.9).
A5: Scenario selectors (Solar + BESS model sheet)
A6: Name of solar plant | B6: P7 | C6: code | D6: P7 Tumkur · P8 Bidar · P12 Kunnoor 4. Also used by the CATL sheets.
A7: BESS duration | B7: 2 | C7: hours | D7: 2 or 4 hours of discharge at the full night connectivity.
A8: Charging case | B8: IEX + T-GNA | C8: text | D8: Own solar = Solar + BESS project. IEX + T-GNA / IEX + GNA = standalone BESS buying on IEX.
A9: Own-solar case: sell market | B9: GDAM | C9: market | D9: Green energy from own solar is sold on GDAM (HTML default). The own-solar dispatch table was computed with GDAM.
A10: IEX cases: buy market | B10: RTM | C10: market
A11: IEX cases: sell market | B11: GDAM | C11: market
A12: Charge window start, 2-hour (IEX cases) | B12: 44 | C12: block 0–95 | D12: 15-minute block index: 44 = 11:00. Charge window length is set by the connectivity limit (Model sheet).
A13: Discharge window start, 2-hour | B13: 76 | C13: block 0–95 | D13: 76 = 19:00. The own-solar dispatch table uses this default.
A14: Charge window start, 4-hour (IEX cases) | B14: 38 | C14: block 0–95 | D14: 38 = 09:30.
A15: Discharge window start, 4-hour | B15: 72 | C15: block 0–95 | D15: 72 = 18:00. The own-solar dispatch table uses this default.
A16: Solar sizing, share of average-day charging need | B16: 1 | C16: % | D16: Own-solar dispatch table was computed at 100%. Changing it resizes solar capex here but not the dispatch energy; re-export from the HTML model to change both.
A17: Booster days on (1 = on, 0 = off) | B17: 0 | C17: switch | D17: Evening discharge sold at the booster price on the booster days.
A18: Booster days from (September day) | B18: 1 | C18: day | D18: IEX cases are fully live. The own-solar booster uplift uses the 1–20 Sep dispatch.
A19: Number of booster days | B19: 20 | C19: days
A20: Booster sell price | B20: 15 | C20: ₹/kWh | D20: User input: ₹15/kWh sell price.
A21: Equity-funded cost on (1 = on, 0 = off) | B21: 1 | C21: switch
A22: Equity-funded cost | B22: 20 | C22: ₹ Cr / yr | D22: User input: ₹20 Cr a year, expensed in the P&L (tax-deductible), excluded from DSCR.
A23: …for the first N years | B23: 2 | C23: years
A25: Capex & land
A26: Solar capex | B26: 2.05 | C26: ₹ Cr / MWp DC | D26: User input.
A27: BESS capex, all-inclusive on nameplate | B27: 0.98 | C27: ₹ Cr / MWh | D27: User input.
A28: Land rate | B28: 35000 | C28: ₹ / acre | D28: User input (plant table).
A29: Land rate basis | B29: Lease | C29: text | D29: Lease = annual lease escalating; Buy = one-time purchase in year 0.
A30: Lease escalation | B30: 0.05 | C30: % / yr
A31: Solar CUF (AC) | B31: 0.3 | C31: % | D31: User input (plant table).
A32: Solar auxiliary consumption | B32: 1 | C32: MW per 300 MWac | D32: User input: 1 MW for the overall plant, scaled to the sized solar.
A34: BESS technical
A35: Depth of discharge | B35: 0.9 | C35: %
A36: Round-trip efficiency (AC-AC) | B36: 0.9 | C36: % | D36: User input.
A37: Capacity fade | B37: 0.015 | C37: % / yr | D37: User input: 1.5%/yr, linear.
A38: HVAC auxiliary, share of discharge | B38: 0.01 | C38: % | D38: User input.
A39: Transformer + line loss to CTU meter | B39: 0.01 | C39: %
A40: ISTS loss on drawal | B40: 0.03 | C40: % | D40: Assumption.
A41: Availability | B41: 0.99 | C41: % | D41: User input.
A42: Augmentation year (0 = none) | B42: 12 | C42: year
A43: Augmentation cost, share of BESS capex | B43: 0.2 | C43: % | D43: Assumption.
A45: Transmission & exchange charges
...

Sheet Prices
A1: IEX MCP average by 15-minute block, ₹/MWh · 2025-09-20 to 2026-09-23 (365 days)
A2: Row 3 is the block position (0–191; blocks 96–191 repeat 0–95 so windows can run past midnight). Source: IEX DAM / GDAM / RTM 15-minute files provided.
A3: Market / block → | B3: 0 | C3: 1 | D3: 2 | E3: 3 | F3: 4 | G3: 5 | H3: 6 | I3: 7 | J3: 8 | K3: 9 | L3: 10 | M3: 11 | N3: 12 | O3: 13 | P3: 14 | Q3: 15 | R3: 16 | S3: 17 | T3: 18 | U3: 19 | V3: 20 | W3: 21 | X3: 22 | Y3: 23 | Z3: 24 | AA3: 25 | AB3: 26 | AC3: 27 | AD3: 28 | AE3: 29 | AF3: 30 | AG3: 31 | AH3: 32 | AI3: 33 | AJ3: 34 | AK3: 35 | AL3: 36 | AM3: 37 | AN3: 38 | AO3: 39 | AP3: 40 | AQ3: 41 | AR3: 42 | AS3: 43 | AT3: 44 | AU3: 45 | AV3: 46 | AW3: 47 | AX3: 48 | AY3: 49 | AZ3: 50 | BA3: 51 | BB3: 52 | BC3: 53 | BD3: 54 | BE3: 55 | BF3: 56 | BG3: 57 | BH3: 58 | BI3: 59 | BJ3: 60 | BK3: 61 | BL3: 62 | BM3: 63 | BN3: 64 | BO3: 65 | BP3: 66 | BQ3: 67 | BR3: 68 | BS3: 69 | BT3: 70 | BU3: 71 | BV3: 72 | BW3: 73 | BX3: 74 | BY3: 75 | BZ3: 76 | CA3: 77 | CB3: 78 | CC3: 79 | CD3: 80 | CE3: 81 | CF3: 82 | CG3: 83 | CH3: 84 | CI3: 85 | CJ3: 86 | CK3: 87 | CL3: 88 | CM3: 89 | CN3: 90 | CO3: 91 | CP3: 92 | CQ3: 93 | CR3: 94 | CS3: 95 | CT3: 96 | CU3: 97 | CV3: 98 | CW3: 99 | CX3: 100 | CY3: 101 | CZ3: 102 | DA3: 103 | DB3: 104 | DC3: 105 | DD3: 106 | DE3: 107 | DF3: 108 | DG3: 109 | DH3: 110 | DI3: 111 | DJ3: 112 | DK3: 113 | DL3: 114 | DM3: 115 | DN3: 116 | DO3: 117 | DP3: 118 | DQ3: 119 | DR3: 120 | DS3: 121 | DT3: 122 | DU3: 123 | DV3: 124 | DW3: 125 | DX3: 126 | DY3: 127 | DZ3: 128 | EA3: 129 | EB3: 130 | EC3: 131 | ED3: 132 | EE3: 133 | EF3: 134 | EG3: 135 | EH3: 136 | EI3: 137 | EJ3: 138 | EK3: 139 | EL3: 140 | EM3: 141 | EN3: 142 | EO3: 143 | EP3: 144 | EQ3: 145 | ER3: 146 | ES3: 147 | ET3: 148 | EU3: 149 | EV3: 150 | EW3: 151 | EX3: 152 | EY3: 153 | EZ3: 154 | FA3: 155 | FB3: 156 | FC3: 157 | FD3: 158 | FE3: 159 | FF3: 160 | FG3: 161 | FH3: 162 | FI3: 163 | FJ3: 164 | FK3: 165 | FL3: 166 | FM3: 167 | FN3: 168 | FO3: 169 | FP3: 170 | FQ3: 171 | FR3: 172 | FS3: 173 | FT3: 174 | FU3: 175 | FV3: 176 | FW3: 177 | FX3: 178 | FY3: 179 | FZ3: 180 | GA3: 181 | GB3: 182 | GC3: 183 | GD3: 184 | GE3: 185 | GF3: 186 | GG3: 187 | GH3: 188 | GI3: 189 | GJ3: 190 | GK3: 191
B4: 00:00 | C4: 00:15 | D4: 00:30 | E4: 00:45 | F4: 01:00 | G4: 01:15 | H4: 01:30 | I4: 01:45 | J4: 02:00 | K4: 02:15 | L4: 02:30 | M4: 02:45 | N4: 03:00 | O4: 03:15 | P4: 03:30 | Q4: 03:45 | R4: 04:00 | S4: 04:15 | T4: 04:30 | U4: 04:45 | V4: 05:00 | W4: 05:15 | X4: 05:30 | Y4: 05:45 | Z4: 06:00 | AA4: 06:15 | AB4: 06:30 | AC4: 06:45 | AD4: 07:00 | AE4: 07:15 | AF4: 07:30 | AG4: 07:45 | AH4: 08:00 | AI4: 08:15 | AJ4: 08:30 | AK4: 08:45 | AL4: 09:00 | AM4: 09:15 | AN4: 09:30 | AO4: 09:45 | AP4: 10:00 | AQ4: 10:15 | AR4: 10:30 | AS4: 10:45 | AT4: 11:00 | AU4: 11:15 | AV4: 11:30 | AW4: 11:45 | AX4: 12:00 | AY4: 12:15 | AZ4: 12:30 | BA4: 12:45 | BB4: 13:00 | BC4: 13:15 | BD4: 13:30 | BE4: 13:45 | BF4: 14:00 | BG4: 14:15 | BH4: 14:30 | BI4: 14:45 | BJ4: 15:00 | BK4: 15:15 | BL4: 15:30 | BM4: 15:45 | BN4: 16:00 | BO4: 16:15 | BP4: 16:30 | BQ4: 16:45 | BR4: 17:00 | BS4: 17:15 | BT4: 17:30 | BU4: 17:45 | BV4: 18:00 | BW4: 18:15 | BX4: 18:30 | BY4: 18:45 | BZ4: 19:00 | CA4: 19:15 | CB4: 19:30 | CC4: 19:45 | CD4: 20:00 | CE4: 20:15 | CF4: 20:30 | CG4: 20:45 | CH4: 21:00 | CI4: 21:15 | CJ4: 21:30 | CK4: 21:45 | CL4: 22:00 | CM4: 22:15 | CN4: 22:30 | CO4: 22:45 | CP4: 23:00 | CQ4: 23:15 | CR4: 23:30 | CS4: 23:45 | CT4: 00:00 | CU4: 00:15 | CV4: 00:30 | CW4: 00:45 | CX4: 01:00 | CY4: 01:15 | CZ4: 01:30 | DA4: 01:45 | DB4: 02:00 | DC4: 02:15 | DD4: 02:30 | DE4: 02:45 | DF4: 03:00 | DG4: 03:15 | DH4: 03:30 | DI4: 03:45 | DJ4: 04:00 | DK4: 04:15 | DL4: 04:30 | DM4: 04:45 | DN4: 05:00 | DO4: 05:15 | DP4: 05:30 | DQ4: 05:45 | DR4: 06:00 | DS4: 06:15 | DT4: 06:30 | DU4: 06:45 | DV4: 07:00 | DW4: 07:15 | DX4: 07:30 | DY4: 07:45 | DZ4: 08:00 | EA4: 08:15 | EB4: 08:30 | EC4: 08:45 | ED4: 09:00 | EE4: 09:15 | EF4: 09:30 | EG4: 09:45 | EH4: 10:00 | EI4: 10:15 | EJ4: 10:30 | EK4: 10:45 | EL4: 11:00 | EM4: 11:15 | EN4: 11:30 | EO4: 11:45 | EP4: 12:00 | EQ4: 12:15 | ER4: 12:30 | ES4: 12:45 | ET4: 13:00 | EU4: 13:15 | EV4: 13:30 | EW4: 13:45 | EX4: 14:00 | EY4: 14:15 | EZ4: 14:30 | FA4: 14:45 | FB4: 15:00 | FC4: 15:15 | FD4: 15:30 | FE4: 15:45 | FF4: 16:00 | FG4: 16:15 | FH4: 16:30 | FI4: 16:45 | FJ4: 17:00 | FK4: 17:15 | FL4: 17:30 | FM4: 17:45 | FN4: 18:00 | FO4: 18:15 | FP4: 18:30 | FQ4: 18:45 | FR4: 19:00 | FS4: 19:15 | FT4: 19:30 | FU4: 19:45 | FV4: 20:00 | FW4: 20:15 | FX4: 20:30 | FY4: 20:45 | FZ4: 21:00 | GA4: 21:15 | GB4: 21:30 | GC4: 21:45 | GD4: 22:00 | GE4: 22:15 | GF4: 22:30 | GG4: 22:45 | GH4: 23:00 | GI4: 23:15 | GJ4: 23:30 | GK4: 23:45
A5: DAM | B5: 5636.31 | C5: 5572.25 | D5: 5519.6 | E5: 5480.04 | F5: 5314.34 | G5: 5212.18 | H5: 5113.96 | I5: 5036.12 | J5: 4850.19 | K5: 4835.98 | L5: 4770.02 | M5: 4748.17 | N5: 4605.4 | O5: 4542.17 | P5: 4512.48 | Q5: 4491.37 | R5: 4476.52 | S5: 4560.99 | T5: 4600.29 | U5: 4660.79 | V5: 4680.77 | W5: 4904.59 | X5: 5029.6 | Y5: 5112.4 | Z5: 5286.2 | AA5: 5468.65 | AB5: 5532.77 | AC5: 5573.73 | AD5: 5538.62 | AE5: 5471.15 | AF5: 5303.05 | AG5: 4870.23 | AH5: 4205.7 | AI5: 3688.1 | AJ5: 3189.15 | AK5: 2897.18 | AL5: 2600.27 | AM5: 2476.37 | AN5: 2323.33 | AO5: 2195.37 | AP5: 1993.6 | AQ5: 1954.39 | AR5: 1906.44 | AS5: 1857.88 | AT5: 1795.24 | AU5: 1787.55 | AV5: 1760.42 | AW5: 1740.58 | AX5: 1686.99 | AY5: 1674.77 | AZ5: 1649.2 | BA5: 1611.26 | BB5: 1477.73 | BC5: 1466.13 | BD5: 1544.97 | BE5: 1617.01 | BF5: 1770.37 | BG5: 1866.57 | BH5: 1984.85 | BI5: 2077.87 | BJ5: 2311.41 | BK5: 2447.48 | BL5: 2660.82 | BM5: 2824.15 | BN5: 2990.45 | BO5: 3131.68 | BP5: 3363.8 | BQ5: 3712.11 | BR5: 4058.81 | BS5: 4539.75 | BT5: 5184.93 | BU5: 5715.53 | BV5: 6040.39 | BW5: 6724.43 | BX5: 7533.29 | BY5: 7938.22 | BZ5: 7997.16 | CA5: 7805.05 | CB5: 7401.2 | CC5: 7070.78 | CD5: 6745.28 | CE5: 6692.92 | CF5: 6641.91 | CG5: 6618.7 | CH5: 6513.92 | CI5: 6484.82 | CJ5: 6439.27 | CK5: 6396.63 | CL5: 6300.95 | CM5: 6352.84 | CN5: 6351.27 | CO5: 6305.36 | CP5: 6176.55 | CQ5: 6116.83 | CR5: 6030.99 | CS5: 5978.47 | CT5: 5636.31 | CU5: 5572.25 | CV5: 5519.6 | CW5: 5480.04 | CX5: 5314.34 | CY5: 5212.18 | CZ5: 5113.96 | DA5: 5036.12 | DB5: 4850.19 | DC5: 4835.98 | DD5: 4770.02 | DE5: 4748.17 | DF5: 4605.4 | DG5: 4542.17 | DH5: 4512.48 | DI5: 4491.37 | DJ5: 4476.52 | DK5: 4560.99 | DL5: 4600.29 | DM5: 4660.79 | DN5: 4680.77 | DO5: 4904.59 | DP5: 5029.6 | DQ5: 5112.4 | DR5: 5286.2 | DS5: 5468.65 | DT5: 5532.77 | DU5: 5573.73 | DV5: 5538.62 | DW5: 5471.15 | DX5: 5303.05 | DY5: 4870.23 | DZ5: 4205.7 | EA5: 3688.1 | EB5: 3189.15 | EC5: 2897.18 | ED5: 2600.27 | EE5: 2476.37 | EF5: 2323.33 | EG5: 2195.37 | EH5: 1993.6 | EI5: 1954.39 | EJ5: 1906.44 | EK5: 1857.88 | EL5: 1795.24 | EM5: 1787.55 | EN5: 1760.42 | EO5: 1740.58 | EP5: 1686.99 | EQ5: 1674.77 | ER5: 1649.2 | ES5: 1611.26 | ET5: 1477.73 | EU5: 1466.13 | EV5: 1544.97 | EW5: 1617.01 | EX5: 1770.37 | EY5: 1866.57 | EZ5: 1984.85 | FA5: 2077.87 | FB5: 2311.41 | FC5: 2447.48 | FD5: 2660.82 | FE5: 2824.15 | FF5: 2990.45 | FG5: 3131.68 | FH5: 3363.8 | FI5: 3712.11 | FJ5: 4058.81 | FK5: 4539.75 | FL5: 5184.93 | FM5: 5715.53 | FN5: 6040.39 | FO5: 6724.43 | FP5: 7533.29 | FQ5: 7938.22 | FR5: 7997.16 | FS5: 7805.05 | FT5: 7401.2 | FU5: 7070.78 | FV5: 6745.28 | FW5: 6692.92 | FX5: 6641.91 | FY5: 6618.7 | FZ5: 6513.92 | GA5: 6484.82 | GB5: 6439.27 | GC5: 6396.63 | GD5: 6300.95 | GE5: 6352.84 | GF5: 6351.27 | GG5: 6305.36 | GH5: 6176.55 | GI5: 6116.83 | GJ5: 6030.99 | GK5: 5978.47
A6: GDAM | B6: 6044.83 | C6: 6032.8 | D6: 6029.71 | E6: 5991.5 | F6: 5894.81 | G6: 5861.7 | H6: 5810.62 | I6: 5742.95 | J6: 5662.87 | K6: 5618.85 | L6: 5626.2 | M6: 5603.75 | N6: 5433.16 | O6: 5435.86 | P6: 5459.55 | Q6: 5469.56 | R6: 5428.36 | S6: 5423.42 | T6: 5430.74 | U6: 5447.45 | V6: 5433.24 | W6: 5492.25 | X6: 5522.31 | Y6: 5564.34 | Z6: 5990.55 | AA6: 6058.76 | AB6: 6074.78 | AC6: 5959.75 | AD6: 6011.7 | AE6: 5640.33 | AF6: 5261.12 | AG6: 4840.03 | AH6: 4426.12 | AI6: 3933.95 | AJ6: 3428.43 | AK6: 2870.42 | AL6: 2696.16 | AM6: 2585.3 | AN6: 2449.84 | AO6: 2376.27 | AP6: 2163.14 | AQ6: 2154.9 | AR6: 2142.93 | AS6: 2118.87 | AT6: 2093.67 | AU6: 2085.8 | AV6: 2059.9 | AW6: 2035.6 | AX6: 1982.22 | AY6: 1944.75 | AZ6: 1927.25 | BA6: 1898.36 | BB6: 1787.53 | BC6: 1778.82 | BD6: 1841.16 | BE6: 1899.44 | BF6: 2023.22 | BG6: 2092.48 | BH6: 2179.82 | BI6: 2248.16 | BJ6: 2558.08 | BK6: 2662.24 | BL6: 2816.82 | BM6: 2968.21 | BN6: 3078.57 | BO6: 3231.01 | BP6: 3444.03 | BQ6: 3742.6 | BR6: 4369.97 | BS6: 4845.14 | BT6: 5480.67 | BU6: 5960.22 | BV6: 7010.96 | BW6: 7650.66 | BX6: 8125.99 | BY6: 8536.24 | BZ6: 8626.85 | CA6: 8390.89 | CB6: 8154.15 | CC6: 7890.35 | CD6: 7609.86 | CE6: 7460.05 | CF6: 7390.38 | CG6: 7374.59 | CH6: 7336.73 | CI6: 7250.89 | CJ6: 7225.65 | CK6: 7210.66 | CL6: 6750.48 | CM6: 6731.28 | CN6: 6727.64 | CO6: 6682.92 | CP6: 6594.48 | CQ6: 6564.37 | CR6: 6543.96 | CS6: 6518.7 | CT6: 6044.83 | CU6: 6032.8 | CV6: 6029.71 | CW6: 5991.5 | CX6: 5894.81 | CY6: 5861.7 | CZ6: 5810.62 | DA6: 5742.95 | DB6: 5662.87 | DC6: 5618.85 | DD6: 5626.2 | DE6: 5603.75 | DF6: 5433.16 | DG6: 5435.86 | DH6: 5459.55 | DI6: 5469.56 | DJ6: 5428.36 | DK6: 5423.42 | DL6: 5430.74 | DM6: 5447.45 | DN6: 5433.24 | DO6: 5492.25 | DP6: 5522.31 | DQ6: 5564.34 | DR6: 5990.55 | DS6: 6058.76 | DT6: 6074.78 | DU6: 5959.75 | DV6: 6011.7 | DW6: 5640.33 | DX6: 5261.12 | DY6: 4840.03 | DZ6: 4426.12 | EA6: 3933.95 | EB6: 3428.43 | EC6: 2870.42 | ED6: 2696.16 | EE6: 2585.3 | EF6: 2449.84 | EG6: 2376.27 | EH6: 2163.14 | EI6: 2154.9 | EJ6: 2142.93 | EK6: 2118.87 | EL6: 2093.67 | EM6: 2085.8 | EN6: 2059.9 | EO6: 2035.6 | EP6: 1982.22 | EQ6: 1944.75 | ER6: 1927.25 | ES6: 1898.36 | ET6: 1787.53 | EU6: 1778.82 | EV6: 1841.16 | EW6: 1899.44 | EX6: 2023.22 | EY6: 2092.48 | EZ6: 2179.82 | FA6: 2248.16 | FB6: 2558.08 | FC6: 2662.24 | FD6: 2816.82 | FE6: 2968.21 | FF6: 3078.57 | FG6: 3231.01 | FH6: 3444.03 | FI6: 3742.6 | FJ6: 4369.97 | FK6: 4845.14 | FL6: 5480.67 | FM6: 5960.22 | FN6: 7010.96 | FO6: 7650.66 | FP6: 8125.99 | FQ6: 8536.24 | FR6: 8626.85 | FS6: 8390.89 | FT6: 8154.15 | FU6: 7890.35 | FV6: 7609.86 | FW6: 7460.05 | FX6: 7390.38 | FY6: 7374.59 | FZ6: 7336.73 | GA6: 7250.89 | GB6: 7225.65 | GC6: 7210.66 | GD6: 6750.48 | GE6: 6731.28 | GF6: 6727.64 | GG6: 6682.92 | GH6: 6594.48 | GI6: 6564.37 | GJ6: 6543.96 | GK6: 6518.7
A7: RTM | B7: 5214.98 | C7: 5195.48 | D7: 5086.54 | E7: 4967.16 | F7: 4764.57 | G7: 4653.84 | H7: 4525.8 | I7: 4382.11 | J7: 4304.69 | K7: 4287.05 | L7: 4152.56 | M7: 4148.56 | N7: 4031.33 | O7: 3994.14 | P7: 3982.34 | Q7: 3954.77 | R7: 4004.67 | S7: 4129.41 | T7: 4163.4 | U7: 4215.82 | V7: 4337.28 | W7: 4585.07 | X7: 4737.03 | Y7: 4800.63 | Z7: 4821.53 | AA7: 5096.8 | AB7: 5117.09 | AC7: 5262.47 | AD7: 5152.91 | AE7: 4977.45 | AF7: 4605.86 | AG7: 4127.85 | AH7: 3729.15 | AI7: 3426.19 | AJ7: 3026.74 | AK7: 2784.52 | AL7: 2729.62 | AM7: 2634.46 | AN7: 2588.53 | AO7: 2385.09 | AP7: 2263.18 | AQ7: 2230.03 | AR7: 2227.28 | AS7: 2140.13 | AT7: 2056.79 | AU7: 2057.02 | AV7: 1984.68 | AW7: 1957.02 | AX7: 1838.78 | AY7: 1839.47 | AZ7: 1779.37 | BA7: 1715.07 | BB7: 1405.84 | BC7: 1453.09 | BD7: 1706.57 | BE7: 1882.82 | BF7: 2014.37 | BG7: 2214.18 | BH7: 2329.55 | BI7: 2497.12 | BJ7: 2599.13 | BK7: 2742.06 | BL7: 2953.44 | BM7: 3111.12 | BN7: 3013.1 | BO7: 3229.74 | BP7: 3492.71 | BQ7: 4047.85 | BR7: 3993.33 | BS7: 4563.86 | BT7: 5130.72 | BU7: 5733.04 | BV7: 5294.96 | BW7: 6131.98 | BX7: 6644.96 | BY7: 6892.9 | BZ7: 6671.43 | CA7: 6709.36 | CB7: 6358.19 | CC7: 6053.68 | CD7: 5791.52 | CE7: 5808.03 | CF7: 5825.08 | CG7: 5887.45 | CH7: 5823.66 | CI7: 5827.64 | CJ7: 5697.16 | CK7: 5583.63 | CL7: 5673.64 | CM7: 5803.06 | CN7: 5797.87 | CO7: 5727.26 | CP7: 5521.91 | CQ7: 5415.09 | CR7: 5192.5 | CS7: 5048.25 | CT7: 5214.98 | CU7: 5195.48 | CV7: 5086.54 | CW7: 4967.16 | CX7: 4764.57 | CY7: 4653.84 | CZ7: 4525.8 | DA7: 4382.11 | DB7: 4304.69 | DC7: 4287.05 | DD7: 4152.56 | DE7: 4148.56 | DF7: 4031.33 | DG7: 3994.14 | DH7: 3982.34 | DI7: 3954.77 | DJ7: 4004.67 | DK7: 4129.41 | DL7: 4163.4 | DM7: 4215.82 | DN7: 4337.28 | DO7: 4585.07 | DP7: 4737.03 | DQ7: 4800.63 | DR7: 4821.53 | DS7: 5096.8 | DT7: 5117.09 | DU7: 5262.47 | DV7: 5152.91 | DW7: 4977.45 | DX7: 4605.86 | DY7: 4127.85 | DZ7: 3729.15 | EA7: 3426.19 | EB7: 3026.74 | EC7: 2784.52 | ED7: 2729.62 | EE7: 2634.46 | EF7: 2588.53 | EG7: 2385.09 | EH7: 2263.18 | EI7: 2230.03 | EJ7: 2227.28 | EK7: 2140.13 | EL7: 2056.79 | EM7: 2057.02 | EN7: 1984.68 | EO7: 1957.02 | EP7: 1838.78 | EQ7: 1839.47 | ER7: 1779.37 | ES7: 1715.07 | ET7: 1405.84 | EU7: 1453.09 | EV7: 1706.57 | EW7: 1882.82 | EX7: 2014.37 | EY7: 2214.18 | EZ7: 2329.55 | FA7: 2497.12 | FB7: 2599.13 | FC7: 2742.06 | FD7: 2953.44 | FE7: 3111.12 | FF7: 3013.1 | FG7: 3229.74 | FH7: 3492.71 | FI7: 4047.85 | FJ7: 3993.33 | FK7: 4563.86 | FL7: 5130.72 | FM7: 5733.04 | FN7: 5294.96 | FO7: 6131.98 | FP7: 6644.96 | FQ7: 6892.9 | FR7: 6671.43 | FS7: 6709.36 | FT7: 6358.19 | FU7: 6053.68 | FV7: 5791.52 | FW7: 5808.03 | FX7: 5825.08 | FY7: 5887.45 | FZ7: 5823.66 | GA7: 5827.64 | GB7: 5697.16 | GC7: 5583.63 | GD7: 5673.64 | GE7: 5803.06 | GF7: 5797.87 | GG7: 5727.26 | GH7: 5521.91 | GI7: 5415.09 | GJ7: 5192.5 | GK7: 5048.25

Sheet SepDays
A1: September daily IEX prices, ₹/MWh, for booster-day calculations
A2: One row per market and September day (latest year in the data: 1–23 Sep 2026, 24–30 Sep 2025). Columns repeat blocks 0–95 twice.
A3: Market | B3: Day / block → | C3: 0 | D3: 1 | E3: 2 | F3: 3 | G3: 4 | H3: 5 | I3: 6 | J3: 7 | K3: 8 | L3: 9 | M3: 10 | N3: 11 | O3: 12 | P3: 13 | Q3: 14 | R3: 15 | S3: 16 | T3: 17 | U3: 18 | V3: 19 | W3: 20 | X3: 21 | Y3: 22 | Z3: 23 | AA3: 24 | AB3: 25 | AC3: 26 | AD3: 27 | AE3: 28 | AF3: 29 | AG3: 30 | AH3: 31 | AI3: 32 | AJ3: 33 | AK3: 34 | AL3: 35 | AM3: 36 | AN3: 37 | AO3: 38 | AP3: 39 | AQ3: 40 | AR3: 41 | AS3: 42 | AT3: 43 | AU3: 44 | AV3: 45 | AW3: 46 | AX3: 47 | AY3: 48 | AZ3: 49 | BA3: 50 | BB3: 51 | BC3: 52 | BD3: 53 | BE3: 54 | BF3: 55 | BG3: 56 | BH3: 57 | BI3: 58 | BJ3: 59 | BK3: 60 | BL3: 61 | BM3: 62 | BN3: 63 | BO3: 64 | BP3: 65 | BQ3: 66 | BR3: 67 | BS3: 68 | BT3: 69 | BU3: 70 | BV3: 71 | BW3: 72 | BX3: 73 | BY3: 74 | BZ3: 75 | CA3: 76 | CB3: 77 | CC3: 78 | CD3: 79 | CE3: 80 | CF3: 81 | CG3: 82 | CH3: 83 | CI3: 84 | CJ3: 85 | CK3: 86 | CL3: 87 | CM3: 88 | CN3: 89 | CO3: 90 | CP3: 91 | CQ3: 92 | CR3: 93 | CS3: 94 | CT3: 95 | CU3: 96 | CV3: 97 | CW3: 98 | CX3: 99 | CY3: 100 | CZ3: 101 | DA3: 102 | DB3: 103 | DC3: 104 | DD3: 105 | DE3: 106 | DF3: 107 | DG3: 108 | DH3: 109 | DI3: 110 | DJ3: 111 | DK3: 112 | DL3: 113 | DM3: 114 | DN3: 115 | DO3: 116 | DP3: 117 | DQ3: 118 | DR3: 119 | DS3: 120 | DT3: 121 | DU3: 122 | DV3: 123 | DW3: 124 | DX3: 125 | DY3: 126 | DZ3: 127 | EA3: 128 | EB3: 129 | EC3: 130 | ED3: 131 | EE3: 132 | EF3: 133 | EG3: 134 | EH3: 135 | EI3: 136 | EJ3: 137 | EK3: 138 | EL3: 139 | EM3: 140 | EN3: 141 | EO3: 142 | EP3: 143 | EQ3: 144 | ER3: 145 | ES3: 146 | ET3: 147 | EU3: 148 | EV3: 149 | EW3: 150 | EX3: 151 | EY3: 152 | EZ3: 153 | FA3: 154 | FB3: 155 | FC3: 156 | FD3: 157 | FE3: 158 | FF3: 159 | FG3: 160 | FH3: 161 | FI3: 162 | FJ3: 163 | FK3: 164 | FL3: 165 | FM3: 166 | FN3: 167 | FO3: 168 | FP3: 169 | FQ3: 170 | FR3: 171 | FS3: 172 | FT3: 173 | FU3: 174 | FV3: 175 | FW3: 176 | FX3: 177 | FY3: 178 | FZ3: 179 | GA3: 180 | GB3: 181 | GC3: 182 | GD3: 183 | GE3: 184 | GF3: 185 | GG3: 186 | GH3: 187 | GI3: 188 | GJ3: 189 | GK3: 190 | GL3: 191
A4: DAM | B4: 1 | C4: 10000 | D4: 10000 | E4: 10000 | F4: 10000 | G4: 10000 | H4: 10000 | I4: 8000 | J4: 8000 | K4: 4401 | L4: 4169 | M4: 4204 | N4: 4500 | O4: 4061 | P4: 4000 | Q4: 3995 | R4: 3899 | S4: 4000 | T4: 4170 | U4: 5000 | V4: 5432 | W4: 10000 | X4: 10000 | Y4: 10000 | Z4: 10000 | AA4: 10000 | AB4: 10000 | AC4: 10000 | AD4: 10000 | AE4: 10000 | AF4: 10000 | AG4: 8364 | AH4: 5910 | AI4: 3439 | AJ4: 3320 | AK4: 3250 | AL4: 3000 | AM4: 2760 | AN4: 2561 | AO4: 2159 | AP4: 2001 | AQ4: 1860 | AR4: 1706 | AS4: 1619 | AT4: 1699 | AU4: 1699 | AV4: 1620 | AW4: 1301 | AX4: 1300 | AY4: 1217 | AZ4: 1235 | BA4: 1221 | BB4: 1175 | BC4: 1112 | BD4: 1112 | BE4: 1263 | BF4: 1368 | BG4: 1500 | BH4: 1564 | BI4: 1860 | BJ4: 1861 | BK4: 2001 | BL4: 2159 | BM4: 2450 | BN4: 2682 | BO4: 3232 | BP4: 3411 | BQ4: 3599 | BR4: 3857 | BS4: 3998 | BT4: 3998 | BU4: 4168 | BV4: 4500 | BW4: 8250 | BX4: 10000 | BY4: 10000 | BZ4: 10000 | CA4: 10000 | CB4: 10000 | CC4: 10000 | CD4: 10000 | CE4: 10000 | CF4: 10000 | CG4: 10000 | CH4: 10000 | CI4: 10000 | CJ4: 10000 | CK4: 10000 | CL4: 10000 | CM4: 10000 | CN4: 10000 | CO4: 10000 | CP4: 10000 | CQ4: 10000 | CR4: 10000 | CS4: 10000 | CT4: 10000 | CU4: 10000 | CV4: 10000 | CW4: 10000 | CX4: 10000 | CY4: 10000 | CZ4: 10000 | DA4: 8000 | DB4: 8000 | DC4: 4401 | DD4: 4169 | DE4: 4204 | DF4: 4500 | DG4: 4061 | DH4: 4000 | DI4: 3995 | DJ4: 3899 | DK4: 4000 | DL4: 4170 | DM4: 5000 | DN4: 5432 | DO4: 10000 | DP4: 10000 | DQ4: 10000 | DR4: 10000 | DS4: 10000 | DT4: 10000 | DU4: 10000 | DV4: 10000 | DW4: 10000 | DX4: 10000 | DY4: 8364 | DZ4: 5910 | EA4: 3439 | EB4: 3320 | EC4: 3250 | ED4: 3000 | EE4: 2760 | EF4: 2561 | EG4: 2159 | EH4: 2001 | EI4: 1860 | EJ4: 1706 | EK4: 1619 | EL4: 1699 | EM4: 1699 | EN4: 1620 | EO4: 1301 | EP4: 1300 | EQ4: 1217 | ER4: 1235 | ES4: 1221 | ET4: 1175 | EU4: 1112 | EV4: 1112 | EW4: 1263 | EX4: 1368 | EY4: 1500 | EZ4: 1564 | FA4: 1860 | FB4: 1861 | FC4: 2001 | FD4: 2159 | FE4: 2450 | FF4: 2682 | FG4: 3232 | FH4: 3411 | FI4: 3599 | FJ4: 3857 | FK4: 3998 | FL4: 3998 | FM4: 4168 | FN4: 4500 | FO4: 8250 | FP4: 10000 | FQ4: 10000 | FR4: 10000 | FS4: 10000 | FT4: 10000 | FU4: 10000 | FV4: 10000 | FW4: 10000 | FX4: 10000 | FY4: 10000 | FZ4: 10000 | GA4: 10000 | GB4: 10000 | GC4: 10000 | GD4: 10000 | GE4: 10000 | GF4: 10000 | GG4: 10000 | GH4: 10000 | GI4: 10000 | GJ4: 10000 | GK4: 10000 | GL4: 10000
A5: DAM | B5: 2 | C5: 10000 | D5: 10000 | E5: 10000 | F5: 10000 | G5: 10000 | H5: 10000 | I5: 10000 | J5: 10000 | K5: 10000 | L5: 10000 | M5: 10000 | N5: 10000 | O5: 10000 | P5: 8500 | Q5: 7501 | R5: 8149 | S5: 10000 | T5: 9991 | U5: 10000 | V5: 10000 | W5: 10000 | X5: 10000 | Y5: 10000 | Z5: 10000 | AA5: 10000 | AB5: 10000 | AC5: 10000 | AD5: 10000 | AE5: 10000 | AF5: 10000 | AG5: 10000 | AH5: 10000 | AI5: 8735 | AJ5: 6500 | AK5: 5060 | AL5: 4300 | AM5: 4020 | AN5: 3741 | AO5: 3500 | AP5: 3201 | AQ5: 2520 | AR5: 2450 | AS5: 2169 | AT5: 2090 | AU5: 1966 | AV5: 1961 | AW5: 1961 | AX5: 1961 | AY5: 1960 | AZ5: 1961 | BA5: 1892 | BB5: 1902 | BC5: 1800 | BD5: 1800 | BE5: 1870 | BF5: 1960 | BG5: 1961 | BH5: 2145 | BI5: 2171 | BJ5: 2279 | BK5: 2520 | BL5: 2708 | BM5: 3045 | BN5: 3562 | BO5: 4020 | BP5: 4321 | BQ5: 5084 | BR5: 5250 | BS5: 5613 | BT5: 6001 | BU5: 10000 | BV5: 10000 | BW5: 10000 | BX5: 10000 | BY5: 10000 | BZ5: 10000 | CA5: 10000 | CB5: 10000 | CC5: 10000 | CD5: 10000 | CE5: 10000 | CF5: 10000 | CG5: 10000 | CH5: 10000 | CI5: 10000 | CJ5: 10000 | CK5: 10000 | CL5: 10000 | CM5: 10000 | CN5: 10000 | CO5: 10000 | CP5: 10000 | CQ5: 10000 | CR5: 10000 | CS5: 10000 | CT5: 10000 | CU5: 10000 | CV5: 10000 | CW5: 10000 | CX5: 10000 | CY5: 10000 | CZ5: 10000 | DA5: 10000 | DB5: 10000 | DC5: 10000 | DD5: 10000 | DE5: 10000 | DF5: 10000 | DG5: 10000 | DH5: 8500 | DI5: 7501 | DJ5: 8149 | DK5: 10000 | DL5: 9991 | DM5: 10000 | DN5: 10000 | DO5: 10000 | DP5: 10000 | DQ5: 10000 | DR5: 10000 | DS5: 10000 | DT5: 10000 | DU5: 10000 | DV5: 10000 | DW5: 10000 | DX5: 10000 | DY5: 10000 | DZ5: 10000 | EA5: 8735 | EB5: 6500 | EC5: 5060 | ED5: 4300 | EE5: 4020 | EF5: 3741 | EG5: 3500 | EH5: 3201 | EI5: 2520 | EJ5: 2450 | EK5: 2169 | EL5: 2090 | EM5: 1966 | EN5: 1961 | EO5: 1961 | EP5: 1961 | EQ5: 1960 | ER5: 1961 | ES5: 1892 | ET5: 1902 | EU5: 1800 | EV5: 1800 | EW5: 1870 | EX5: 1960 | EY5: 1961 | EZ5: 2145 | FA5: 2171 | FB5: 2279 | FC5: 2520 | FD5: 2708 | FE5: 3045 | FF5: 3562 | FG5: 4020 | FH5: 4321 | FI5: 5084 | FJ5: 5250 | FK5: 5613 | FL5: 6001 | FM5: 10000 | FN5: 10000 | FO5: 10000 | FP5: 10000 | FQ5: 10000 | FR5: 10000 | FS5: 10000 | FT5: 10000 | FU5: 10000 | FV5: 10000 | FW5: 10000 | FX5: 10000 | FY5: 10000 | FZ5: 10000 | GA5: 10000 | GB5: 10000 | GC5: 10000 | GD5: 10000 | GE5: 10000 | GF5: 10000 | GG5: 10000 | GH5: 10000 | GI5: 10000 | GJ5: 10000 | GK5: 10000 | GL5: 10000
A6: DAM | B6: 3 | C6: 10000 | D6: 10000 | E6: 10000 | F6: 10000 | G6: 10000 | H6: 10000 | I6: 10000 | J6: 10000 | K6: 10000 | L6: 10000 | M6: 10000 | N6: 10000 | O6: 10000 | P6: 10000 | Q6: 10000 | R6: 10000 | S6: 10000 | T6: 10000 | U6: 10000 | V6: 10000 | W6: 10000 | X6: 10000 | Y6: 10000 | Z6: 10000 | AA6: 10000 | AB6: 10000 | AC6: 10000 | AD6: 10000 | AE6: 10000 | AF6: 10000 | AG6: 10000 | AH6: 10000 | AI6: 10000 | AJ6: 8001 | AK6: 6902 | AL6: 4913 | AM6: 4118 | AN6: 3712 | AO6: 3289 | AP6: 3067 | AQ6: 2514 | AR6: 2279 | AS6: 2231 | AT6: 2199 | AU6: 2164 | AV6: 2159 | AW6: 2101 | AX6: 2075 | AY6: 1991 | AZ6: 1967 | BA6: 1960 | BB6: 1941 | BC6: 1870 | BD6: 1885 | BE6: 1960 | BF6: 1967 | BG6: 2158 | BH6: 2200 | BI6: 2545 | BJ6: 2709 | BK6: 3257 | BL6: 3475 | BM6: 3500 | BN6: 3614 | BO6: 4116 | BP6: 4364 | BQ6: 5484 | BR6: 5571 | BS6: 10000 | BT6: 10000 | BU6: 10000 | BV6: 10000 | BW6: 10000 | BX6: 10000 | BY6: 10000 | BZ6: 10000 | CA6: 10000 | CB6: 10000 | CC6: 10000 | CD6: 10000 | CE6: 10000 | CF6: 10000 | CG6: 10000 | CH6: 10000 | CI6: 10000 | CJ6: 10000 | CK6: 10000 | CL6: 10000 | CM6: 10000 | CN6: 10000 | CO6: 10000 | CP6: 10000 | CQ6: 10000 | CR6: 10000 | CS6: 10000 | CT6: 10000 | CU6: 10000 | CV6: 10000 | CW6: 10000 | CX6: 10000 | CY6: 10000 | CZ6: 10000 | DA6: 10000 | DB6: 10000 | DC6: 10000 | DD6: 10000 | DE6: 10000 | DF6: 10000 | DG6: 10000 | DH6: 10000 | DI6: 10000 | DJ6: 10000 | DK6: 10000 | DL6: 10000 | DM6: 10000 | DN6: 10000 | DO6: 10000 | DP6: 10000 | DQ6: 10000 | DR6: 10000 | DS6: 10000 | DT6: 10000 | DU6: 10000 | DV6: 10000 | DW6: 10000 | DX6: 10000 | DY6: 10000 | DZ6: 10000 | EA6: 10000 | EB6: 8001 | EC6: 6902 | ED6: 4913 | EE6: 4118 | EF6: 3712 | EG6: 3289 | EH6: 3067 | EI6: 2514 | EJ6: 2279 | EK6: 2231 | EL6: 2199 | EM6: 2164 | EN6: 2159 | EO6: 2101 | EP6: 2075 | EQ6: 1991 | ER6: 1967 | ES6: 1960 | ET6: 1941 | EU6: 1870 | EV6: 1885 | EW6: 1960 | EX6: 1967 | EY6: 2158 | EZ6: 2200 | FA6: 2545 | FB6: 2709 | FC6: 3257 | FD6: 3475 | FE6: 3500 | FF6: 3614 | FG6: 4116 | FH6: 4364 | FI6: 5484 | FJ6: 5571 | FK6: 10000 | FL6: 10000 | FM6: 10000 | FN6: 10000 | FO6: 10000 | FP6: 10000 | FQ6: 10000 | FR6: 10000 | FS6: 10000 | FT6: 10000 | FU6: 10000 | FV6: 10000 | FW6: 10000 | FX6: 10000 | FY6: 10000 | FZ6: 10000 | GA6: 10000 | GB6: 10000 | GC6: 10000 | GD6: 10000 | GE6: 10000 | GF6: 10000 | GG6: 10000 | GH6: 10000 | GI6: 10000 | GJ6: 10000 | GK6: 10000 | GL6: 10000
A7: DAM | B7: 4 | C7: 10000 | D7: 10000 | E7: 10000 | F7: 10000 | G7: 10000 | H7: 10000 | I7: 10000 | J7: 10000 | K7: 10000 | L7: 10000 | M7: 10000 | N7: 10000 | O7: 10000 | P7: 10000 | Q7: 10000 | R7: 10000 | S7: 10000 | T7: 10000 | U7: 10000 | V7: 10000 | W7: 10000 | X7: 10000 | Y7: 10000 | Z7: 10000 | AA7: 10000 | AB7: 10000 | AC7: 10000 | AD7: 10000 | AE7: 10000 | AF7: 10000 | AG7: 10000 | AH7: 10000 | AI7: 10000 | AJ7: 10000 | AK7: 4364 | AL7: 4012 | AM7: 3311 | AN7: 3000 | AO7: 2670 | AP7: 2661 | AQ7: 2449 | AR7: 2279 | AS7: 2093 | AT7: 2094 | AU7: 1966 | AV7: 1966 | AW7: 1966 | AX7: 1961 | AY7: 1916 | AZ7: 1897 | BA7: 1701 | BB7: 1701 | BC7: 1700 | BD7: 1700 | BE7: 1700 | BF7: 1700 | BG7: 1751 | BH7: 1960 | BI7: 2159 | BJ7: 2341 | BK7: 2671 | BL7: 2871 | BM7: 3160 | BN7: 3301 | BO7: 3499 | BP7: 3974 | BQ7: 4020 | BR7: 4167 | BS7: 6501 | BT7: 9999 | BU7: 10000 | BV7: 10000 | BW7: 10000 | BX7: 10000 | BY7: 10000 | BZ7: 10000 | CA7: 10000 | CB7: 10000 | CC7: 10000 | CD7: 10000 | CE7: 10000 | CF7: 10000 | CG7: 10000 | CH7: 10000 | CI7: 10000 | CJ7: 10000 | CK7: 10000 | CL7: 10000 | CM7: 10000 | CN7: 10000 | CO7: 10000 | CP7: 10000 | CQ7: 10000 | CR7: 10000 | CS7: 10000 | CT7: 10000 | CU7: 10000 | CV7: 10000 | CW7: 10000 | CX7: 10000 | CY7: 10000 | CZ7: 10000 | DA7: 10000 | DB7: 10000 | DC7: 10000 | DD7: 10000 | DE7: 10000 | DF7: 10000 | DG7: 10000 | DH7: 10000 | DI7: 10000 | DJ7: 10000 | DK7: 10000 | DL7: 10000 | DM7: 10000 | DN7: 10000 | DO7: 10000 | DP7: 10000 | DQ7: 10000 | DR7: 10000 | DS7: 10000 | DT7: 10000 | DU7: 10000 | DV7: 10000 | DW7: 10000 | DX7: 10000 | DY7: 10000 | DZ7: 10000 | EA7: 10000 | EB7: 10000 | EC7: 4364 | ED7: 4012 | EE7: 3311 | EF7: 3000 | EG7: 2670 | EH7: 2661 | EI7: 2449 | EJ7: 2279 | EK7: 2093 | EL7: 2094 | EM7: 1966 | EN7: 1966 | EO7: 1966 | EP7: 1961 | EQ7: 1916 | ER7: 1897 | ES7: 1701 | ET7: 1701 | EU7: 1700 | EV7: 1700 | EW7: 1700 | EX7: 1700 | EY7: 1751 | EZ7: 1960 | FA7: 2159 | FB7: 2341 | FC7: 2671 | FD7: 2871 | FE7: 3160 | FF7: 3301 | FG7: 3499 | FH7: 3974 | FI7: 4020 | FJ7: 4167 | FK7: 6501 | FL7: 9999 | FM7: 10000 | FN7: 10000 | FO7: 10000 | FP7: 10000 | FQ7: 10000 | FR7: 10000 | FS7: 10000 | FT7: 10000 | FU7: 10000 | FV7: 10000 | FW7: 10000 | FX7: 10000 | FY7: 10000 | FZ7: 10000 | GA7: 10000 | GB7: 10000 | GC7: 10000 | GD7: 10000 | GE7: 10000 | GF7: 10000 | GG7: 10000 | GH7: 10000 | GI7: 10000 | GJ7: 10000 | GK7: 10000 | GL7: 10000
A8: DAM | B8: 5 | C8: 10000 | D8: 10000 | E8: 10000 | F8: 10000 | G8: 10000 | H8: 10000 | I8: 10000 | J8: 10000 | K8: 10000 | L8: 10000 | M8: 10000 | N8: 10000 | O8: 10000 | P8: 10000 | Q8: 10000 | R8: 10000 | S8: 10000 | T8: 10000 | U8: 10000 | V8: 10000 | W8: 10000 | X8: 10000 | Y8: 10000 | Z8: 10000 | AA8: 10000 | AB8: 10000 | AC8: 10000 | AD8: 10000 | AE8: 10000 | AF8: 10000 | AG8: 10000 | AH8: 10000 | AI8: 10000 | AJ8: 10000 | AK8: 10000 | AL8: 10000 | AM8: 5571 | AN8: 5400 | AO8: 3988 | AP8: 3966 | AQ8: 3528 | AR8: 3408 | AS8: 3370 | AT8: 3296 | AU8: 3050 | AV8: 2999 | AW8: 2900 | AX8: 2850 | AY8: 2744 | AZ8: 2713 | BA8: 2707 | BB8: 2728 | BC8: 2723 | BD8: 2747 | BE8: 2850 | BF8: 2900 | BG8: 3251 | BH8: 3329 | BI8: 3466 | BJ8: 3545 | BK8: 3966 | BL8: 4000 | BM8: 4938 | BN8: 5512 | BO8: 9992 | BP8: 9994 | BQ8: 10000 | BR8: 10000 | BS8: 10000 | BT8: 10000 | BU8: 10000 | BV8: 10000 | BW8: 10000 | BX8: 10000 | BY8: 10000 | BZ8: 10000 | CA8: 10000 | CB8: 10000 | CC8: 10000 | CD8: 10000 | CE8: 10000 | CF8: 10000 | CG8: 10000 | CH8: 10000 | CI8: 10000 | CJ8: 10000 | CK8: 10000 | CL8: 10000 | CM8: 10000 | CN8: 10000 | CO8: 10000 | CP8: 10000 | CQ8: 10000 | CR8: 10000 | CS8: 10000 | CT8: 10000 | CU8: 10000 | CV8: 10000 | CW8: 10000 | CX8: 10000 | CY8: 10000 | CZ8: 10000 | DA8: 10000 | DB8: 10000 | DC8: 10000 | DD8: 10000 | DE8: 10000 | DF8: 10000 | DG8: 10000 | DH8: 10000 | DI8: 10000 | DJ8: 10000 | DK8: 10000 | DL8: 10000 | DM8: 10000 | DN8: 10000 | DO8: 10000 | DP8: 10000 | DQ8: 10000 | DR8: 10000 | DS8: 10000 | DT8: 10000 | DU8: 10000 | DV8: 10000 | DW8: 10000 | DX8: 10000 | DY8: 10000 | DZ8: 10000 | EA8: 10000 | EB8: 10000 | EC8: 10000 | ED8: 10000 | EE8: 5571 | EF8: 5400 | EG8: 3988 | EH8: 3966 | EI8: 3528 | EJ8: 3408 | EK8: 3370 | EL8: 3296 | EM8: 3050 | EN8: 2999 | EO8: 2900 | EP8: 2850 | EQ8: 2744 | ER8: 2713 | ES8: 2707 | ET8: 2728 | EU8: 2723 | EV8: 2747 | EW8: 2850 | EX8: 2900 | EY8: 3251 | EZ8: 3329 | FA8: 3466 | FB8: 3545 | FC8: 3966 | FD8: 4000 | FE8: 4938 | FF8: 5512 | FG8: 9992 | FH8: 9994 | FI8: 10000 | FJ8: 10000 | FK8: 10000 | FL8: 10000 | FM8: 10000 | FN8: 10000 | FO8: 10000 | FP8: 10000 | FQ8: 10000 | FR8: 10000 | FS8: 10000 | FT8: 10000 | FU8: 10000 | FV8: 10000 | FW8: 10000 | FX8: 10000 | FY8: 10000 | FZ8: 10000 | GA8: 10000 | GB8: 10000 | GC8: 10000 | GD8: 10000 | GE8: 10000 | GF8: 10000 | GG8: 10000 | GH8: 10000 | GI8: 10000 | GJ8: 10000 | GK8: 10000 | GL8: 10000
A9: DAM | B9: 6 | C9: 10000 | D9: 10000 | E9: 10000 | F9: 10000 | G9: 10000 | H9: 10000 | I9: 10000 | J9: 10000 | K9: 10000 | L9: 10000 | M9: 10000 | N9: 10000 | O9: 10000 | P9: 10000 | Q9: 10000 | R9: 10000 | S9: 10000 | T9: 10000 | U9: 10000 | V9: 10000 | W9: 10000 | X9: 10000 | Y9: 10000 | Z9: 10000 | AA9: 10000 | AB9: 10000 | AC9: 10000 | AD9: 10000 | AE9: 10000 | AF9: 10000 | AG9: 10000 | AH9: 10000 | AI9: 10000 | AJ9: 6072 | AK9: 5821 | AL9: 4913 | AM9: 3851 | AN9: 3545 | AO9: 3200 | AP9: 2802 | AQ9: 2639 | AR9: 2132 | AS9: 2171 | AT9: 2163 | AU9: 2101 | AV9: 2100 | AW9: 2000 | AX9: 1966 | AY9: 1961 | AZ9: 1960 | BA9: 1936 | BB9: 1904 | BC9: 1860 | BD9: 1871 | BE9: 1906 | BF9: 1966 | BG9: 2101 | BH9: 2370 | BI9: 2480 | BJ9: 2660 | BK9: 2862 | BL9: 3002 | BM9: 3385 | BN9: 3500 | BO9: 3747 | BP9: 5512 | BQ9: 10000 | BR9: 10000 | BS9: 10000 | BT9: 10000 | BU9: 10000 | BV9: 10000 | BW9: 10000 | BX9: 10000 | BY9: 10000 | BZ9: 10000 | CA9: 10000 | CB9: 10000 | CC9: 10000 | CD9: 10000 | CE9: 10000 | CF9: 10000 | CG9: 10000 | CH9: 10000 | CI9: 10000 | CJ9: 10000 | CK9: 10000 | CL9: 10000 | CM9: 10000 | CN9: 10000 | CO9: 10000 | CP9: 10000 | CQ9: 10000 | CR9: 10000 | CS9: 10000 | CT9: 10000 | CU9: 10000 | CV9: 10000 | CW9: 10000 | CX9: 10000 | CY9: 10000 | CZ9: 10000 | DA9: 10000 | DB9: 10000 | DC9: 10000 | DD9: 10000 | DE9: 10000 | DF9: 10000 | DG9: 10000 | DH9: 10000 | DI9: 10000 | DJ9: 10000 | DK9: 10000 | DL9: 10000 | DM9: 10000 | DN9: 10000 | DO9: 10000 | DP9: 10000 | DQ9: 10000 | DR9: 10000 | DS9: 10000 | DT9: 10000 | DU9: 10000 | DV9: 10000 | DW9: 10000 | DX9: 10000 | DY9: 10000 | DZ9: 10000 | EA9: 10000 | EB9: 6072 | EC9: 5821 | ED9: 4913 | EE9: 3851 | EF9: 3545 | EG9: 3200 | EH9: 2802 | EI9: 2639 | EJ9: 2132 | EK9: 2171 | EL9: 2163 | EM9: 2101 | EN9: 2100 | EO9: 2000 | EP9: 1966 | EQ9: 1961 | ER9: 1960 | ES9: 1936 | ET9: 1904 | EU9: 1860 | EV9: 1871 | EW9: 1906 | EX9: 1966 | EY9: 2101 | EZ9: 2370 | FA9: 2480 | FB9: 2660 | FC9: 2862 | FD9: 3002 | FE9: 3385 | FF9: 3500 | FG9: 3747 | FH9: 5512 | FI9: 10000 | FJ9: 10000 | FK9: 10000 | FL9: 10000 | FM9: 10000 | FN9: 10000 | FO9: 10000 | FP9: 10000 | FQ9: 10000 | FR9: 10000 | FS9: 10000 | FT9: 10000 | FU9: 10000 | FV9: 10000 | FW9: 10000 | FX9: 10000 | FY9: 10000 | FZ9: 10000 | GA9: 10000 | GB9: 10000 | GC9: 10000 | GD9: 10000 | GE9: 10000 | GF9: 10000 | GG9: 10000 | GH9: 10000 | GI9: 10000 | GJ9: 10000 | GK9: 10000 | GL9: 10000
A10: DAM | B10: 7 | C10: 10000 | D10: 10000 | E10: 10000 | F10: 10000 | G10: 10000 | H10: 10000 | I10: 10000 | J10: 10000 | K10: 10000 | L10: 10000 | M10: 10000 | N10: 10000 | O10: 10000 | P10: 10000 | Q10: 10000 | R10: 10000 | S10: 10000 | T10: 10000 | U10: 10000 | V10: 10000 | W10: 10000 | X10: 10000 | Y10: 10000 | Z10: 10000 | AA10: 10000 | AB10: 10000 | AC10: 10000 | AD10: 10000 | AE10: 10000 | AF10: 10000 | AG10: 10000 | AH10: 10000 | AI10: 10000 | AJ10: 10000 | AK10: 10000 | AL10: 10000 | AM10: 9991 | AN10: 5290 | AO10: 3979 | AP10: 3570 | AQ10: 3545 | AR10: 3545 | AS10: 3484 | AT10: 3421 | AU10: 3002 | AV10: 2999 | AW10: 2999 | AX10: 2992 | AY10: 2741 | AZ10: 2680 | BA10: 2660 | BB10: 2640 | BC10: 2326 | BD10: 2513 | BE10: 2710 | BF10: 2780 | BG10: 3200 | BH10: 3201 | BI10: 3446 | BJ10: 3545 | BK10: 3857 | BL10: 4091 | BM10: 5500 | BN10: 6000 | BO10: 10000 | BP10: 10000 | BQ10: 10000 | BR10: 10000 | BS10: 10000 | BT10: 10000 | BU10: 10000 | BV10: 10000 | BW10: 10000 | BX10: 10000 | BY10: 10000 | BZ10: 10000 | CA10: 10000 | CB10: 10000 | CC10: 10000 | CD10: 10000 | CE10: 10000 | CF10: 10000 | CG10: 10000 | CH10: 10000 | CI10: 10000 | CJ10: 10000 | CK10: 10000 | CL10: 10000 | CM10: 10000 | CN10: 10000 | CO10: 10000 | CP10: 10000 | CQ10: 10000 | CR10: 10000 | CS10: 10000 | CT10: 10000 | CU10: 10000 | CV10: 10000 | CW10: 10000 | CX10: 10000 | CY10: 10000 | CZ10: 10000 | DA10: 10000 | DB10: 10000 | DC10: 10000 | DD10: 10000 | DE10: 10000 | DF10: 10000 | DG10: 10000 | DH10: 10000 | DI10: 10000 | DJ10: 10000 | DK10: 10000 | DL10: 10000 | DM10: 10000 | DN10: 10000 | DO10: 10000 | DP10: 10000 | DQ10: 10000 | DR10: 10000 | DS10: 10000 | DT10: 10000 | DU10: 10000 | DV10: 10000 | DW10: 10000 | DX10: 10000 | DY10: 10000 | DZ10: 10000 | EA10: 10000 | EB10: 10000 | EC10: 10000 | ED10: 10000 | EE10: 9991 | EF10: 5290 | EG10: 3979 | EH10: 3570 | EI10: 3545 | EJ10: 3545 | EK10: 3484 | EL10: 3421 | EM10: 3002 | EN10: 2999 | EO10: 2999 | EP10: 2992 | EQ10: 2741 | ER10: 2680 | ES10: 2660 | ET10: 2640 | EU10: 2326 | EV10: 2513 | EW10: 2710 | EX10: 2780 | EY10: 3200 | EZ10: 3201 | FA10: 3446 | FB10: 3545 | FC10: 3857 | FD10: 4091 | FE10: 5500 | FF10: 6000 | FG10: 10000 | FH10: 10000 | FI10: 10000 | FJ10: 10000 | FK10: 10000 | FL10: 10000 | FM10: 10000 | FN10: 10000 | FO10: 10000 | FP10: 10000 | FQ10: 10000 | FR10: 10000 | FS10: 10000 | FT10: 10000 | FU10: 10000 | FV10: 10000 | FW10: 10000 | FX10: 10000 | FY10: 10000 | FZ10: 10000 | GA10: 10000 | GB10: 10000 | GC10: 10000 | GD10: 10000 | GE10: 10000 | GF10: 10000 | GG10: 10000 | GH10: 10000 | GI10: 10000 | GJ10: 10000 | GK10: 10000 | GL10: 10000
A11: DAM | B11: 8 | C11: 10000 | D11: 10000 | E11: 10000 | F11: 10000 | G11: 10000 | H11: 10000 | I11: 10000 | J11: 10000 | K11: 10000 | L11: 10000 | M11: 10000 | N11: 10000 | O11: 10000 | P11: 10000 | Q11: 10000 | R11: 10000 | S11: 10000 | T11: 10000 | U11: 10000 | V11: 10000 | W11: 10000 | X11: 10000 | Y11: 10000 | Z11: 10000 | AA11: 10000 | AB11: 10000 | AC11: 10000 | AD11: 10000 | AE11: 10000 | AF11: 10000 | AG11: 10000 | AH11: 10000 | AI11: 10000 | AJ11: 9999 | AK11: 9999 | AL11: 3980 | AM11: 3980 | AN11: 3746 | AO11: 3528 | AP11: 3100 | AQ11: 2901 | AR11: 2760 | AS11: 2760 | AT11: 2814 | AU11: 2780 | AV11: 2741 | AW11: 2661 | AX11: 2660 | AY11: 2428 | AZ11: 2370 | BA11: 2245 | BB11: 2110 | BC11: 2017 | BD11: 2023 | BE11: 2130 | BF11: 2171 | BG11: 2571 | BH11: 2738 | BI11: 2740 | BJ11: 3201 | BK11: 3510 | BL11: 3580 | BM11: 4050 | BN11: 4301 | BO11: 9500 | BP11: 10000 | BQ11: 10000 | BR11: 10000 | BS11: 10000 | BT11: 10000 | BU11: 10000 | BV11: 10000 | BW11: 10000 | BX11: 10000 | BY11: 10000 | BZ11: 10000 | CA11: 10000 | CB11: 10000 | CC11: 10000 | CD11: 10000 | CE11: 10000 | CF11: 10000 | CG11: 10000 | CH11: 10000 | CI11: 10000 | CJ11: 10000 | CK11: 10000 | CL11: 10000 | CM11: 10000 | CN11: 10000 | CO11: 10000 | CP11: 10000 | CQ11: 10000 | CR11: 10000 | CS11: 10000 | CT11: 10000 | CU11: 10000 | CV11: 10000 | CW11: 10000 | CX11: 10000 | CY11: 10000 | CZ11: 10000 | DA11: 10000 | DB11: 10000 | DC11: 10000 | DD11: 10000 | DE11: 10000 | DF11: 10000 | DG11: 10000 | DH11: 10000 | DI11: 10000 | DJ11: 10000 | DK11: 10000 | DL11: 10000 | DM11: 10000 | DN11: 10000 | DO11: 10000 | DP11: 10000 | DQ11: 10000 | DR11: 10000 | DS11: 10000 | DT11: 10000 | DU11: 10000 | DV11: 10000 | DW11: 10000 | DX11: 10000 | DY11: 10000 | DZ11: 10000 | EA11: 10000 | EB11: 9999 | EC11: 9999 | ED11: 3980 | EE11: 3980 | EF11: 3746 | EG11: 3528 | EH11: 3100 | EI11: 2901 | EJ11: 2760 | EK11: 2760 | EL11: 2814 | EM11: 2780 | EN11: 2741 | EO11: 2661 | EP11: 2660 | EQ11: 2428 | ER11: 2370 | ES11: 2245 | ET11: 2110 | EU11: 2017 | EV11: 2023 | EW11: 2130 | EX11: 2171 | EY11: 2571 | EZ11: 2738 | FA11: 2740 | FB11: 3201 | FC11: 3510 | FD11: 3580 | FE11: 4050 | FF11: 4301 | FG11: 9500 | FH11: 10000 | FI11: 10000 | FJ11: 10000 | FK11: 10000 | FL11: 10000 | FM11: 10000 | FN11: 10000 | FO11: 10000 | FP11: 10000 | FQ11: 10000 | FR11: 10000 | FS11: 10000 | FT11: 10000 | FU11: 10000 | FV11: 10000 | FW11: 10000 | FX11: 10000 | FY11: 10000 | FZ11: 10000 | GA11: 10000 | GB11: 10000 | GC11: 10000 | GD11: 10000 | GE11: 10000 | GF11: 10000 | GG11: 10000 | GH11: 10000 | GI11: 10000 | GJ11: 10000 | GK11: 10000 | GL11: 10000
A12: DAM | B12: 9 | C12: 10000 | D12: 10000 | E12: 10000 | F12: 10000 | G12: 10000 | H12: 10000 | I12: 10000 | J12: 10000 | K12: 10000 | L12: 10000 | M12: 10000 | N12: 10000 | O12: 10000 | P12: 10000 | Q12: 10000 | R12: 10000 | S12: 10000 | T12: 10000 | U12: 10000 | V12: 10000 | W12: 10000 | X12: 10000 | Y12: 10000 | Z12: 10000 | AA12: 10000 | AB12: 10000 | AC12: 10000 | AD12: 10000 | AE12: 10000 | AF12: 10000 | AG12: 10000 | AH12: 10000 | AI12: 10000 | AJ12: 10000 | AK12: 9001 | AL12: 7842 | AM12: 5001 | AN12: 3788 | AO12: 3500 | AP12: 3299 | AQ12: 2621 | AR12: 2251 | AS12: 2171 | AT12: 2601 | AU12: 2441 | AV12: 2190 | AW12: 2170 | AX12: 2168 | AY12: 2168 | AZ12: 2163 | BA12: 2162 | BB12: 2093 | BC12: 1999 | BD12: 1999 | BE12: 2094 | BF12: 2170 | BG12: 2611 | BH12: 2850 | BI12: 2988 | BJ12: 3088 | BK12: 3711 | BL12: 4003 | BM12: 5500 | BN12: 6000 | BO12: 10000 | BP12: 10000 | BQ12: 10000 | BR12: 10000 | BS12: 10000 | BT12: 10000 | BU12: 10000 | BV12: 10000 | BW12: 10000 | BX12: 10000 | BY12: 10000 | BZ12: 10000 | CA12: 10000 | CB12: 10000 | CC12: 10000 | CD12: 10000 | CE12: 10000 | CF12: 10000 | CG12: 10000 | CH12: 10000 | CI12: 10000 | CJ12: 10000 | CK12: 10000 | CL12: 10000 | CM12: 10000 | CN12: 10000 | CO12: 10000 | CP12: 10000 | CQ12: 10000 | CR12: 10000 | CS12: 10000 | CT12: 10000 | CU12: 10000 | CV12: 10000 | CW12: 10000 | CX12: 10000 | CY12: 10000 | CZ12: 10000 | DA12: 10000 | DB12: 10000 | DC12: 10000 | DD12: 10000 | DE12: 10000 | DF12: 10000 | DG12: 10000 | DH12: 10000 | DI12: 10000 | DJ12: 10000 | DK12: 10000 | DL12: 10000 | DM12: 10000 | DN12: 10000 | DO12: 10000 | DP12: 10000 | DQ12: 10000 | DR12: 10000 | DS12: 10000 | DT12: 10000 | DU12: 10000 | DV12: 10000 | DW12: 10000 | DX12: 10000 | DY12: 10000 | DZ12: 10000 | EA12: 10000 | EB12: 10000 | EC12: 9001 | ED12: 7842 | EE12: 5001 | EF12: 3788 | EG12: 3500 | EH12: 3299 | EI12: 2621 | EJ12: 2251 | EK12: 2171 | EL12: 2601 | EM12: 2441 | EN12: 2190 | EO12: 2170 | EP12: 2168 | EQ12: 2168 | ER12: 2163 | ES12: 2162 | ET12: 2093 | EU12: 1999 | EV12: 1999 | EW12: 2094 | EX12: 2170 | EY12: 2611 | EZ12: 2850 | FA12: 2988 | FB12: 3088 | FC12: 3711 | FD12: 4003 | FE12: 5500 | FF12: 6000 | FG12: 10000 | FH12: 10000 | FI12: 10000 | FJ12: 10000 | FK12: 10000 | FL12: 10000 | FM12: 10000 | FN12: 10000 | FO12: 10000 | FP12: 10000 | FQ12: 10000 | FR12: 10000 | FS12: 10000 | FT12: 10000 | FU12: 10000 | FV12: 10000 | FW12: 10000 | FX12: 10000 | FY12: 10000 | FZ12: 10000 | GA12: 10000 | GB12: 10000 | GC12: 10000 | GD12: 10000 | GE12: 10000 | GF12: 10000 | GG12: 10000 | GH12: 10000 | GI12: 10000 | GJ12: 10000 | GK12: 10000 | GL12: 10000
A13: DAM | B13: 10 | C13: 10000 | D13: 10000 | E13: 10000 | F13: 10000 | G13: 10000 | H13: 10000 | I13: 10000 | J13: 10000 | K13: 10000 | L13: 10000 | M13: 10000 | N13: 10000 | O13: 10000 | P13: 10000 | Q13: 10000 | R13: 10000 | S13: 10000 | T13: 10000 | U13: 10000 | V13: 10000 | W13: 10000 | X13: 10000 | Y13: 10000 | Z13: 10000 | AA13: 10000 | AB13: 10000 | AC13: 10000 | AD13: 10000 | AE13: 10000 | AF13: 10000 | AG13: 10000 | AH13: 10000 | AI13: 10000 | AJ13: 10000 | AK13: 10000 | AL13: 10000 | AM13: 5820 | AN13: 4092 | AO13: 3743 | AP13: 3441 | AQ13: 3463 | AR13: 3440 | AS13: 3393 | AT13: 3200 | AU13: 2999 | AV13: 2980 | AW13: 2781 | AX13: 2760 | AY13: 2661 | AZ13: 2660 | BA13: 2660 | BB13: 2660 | BC13: 2612 | BD13: 2612 | BE13: 2688 | BF13: 2850 | BG13: 3049 | BH13: 3302 | BI13: 3491 | BJ13: 3710 | BK13: 4091 | BL13: 5499 | BM13: 7501 | BN13: 10000 | BO13: 10000 | BP13: 10000 | BQ13: 10000 | BR13: 10000 | BS13: 10000 | BT13: 10000 | BU13: 10000 | BV13: 10000 | BW13: 10000 | BX13: 10000 | BY13: 10000 | BZ13: 10000 | CA13: 10000 | CB13: 10000 | CC13: 10000 | CD13: 10000 | CE13: 10000 | CF13: 10000 | CG13: 10000 | CH13: 10000 | CI13: 10000 | CJ13: 10000 | CK13: 10000 | CL13: 10000 | CM13: 10000 | CN13: 10000 | CO13: 10000 | CP13: 10000 | CQ13: 10000 | CR13: 10000 | CS13: 10000 | CT13: 10000 | CU13: 10000 | CV13: 10000 | CW13: 10000 | CX13: 10000 | CY13: 10000 | CZ13: 10000 | DA13: 10000 | DB13: 10000 | DC13: 10000 | DD13: 10000 | DE13: 10000 | DF13: 10000 | DG13: 10000 | DH13: 10000 | DI13: 10000 | DJ13: 10000 | DK13: 10000 | DL13: 10000 | DM13: 10000 | DN13: 10000 | DO13: 10000 | DP13: 10000 | DQ13: 10000 | DR13: 10000 | DS13: 10000 | DT13: 10000 | DU13: 10000 | DV13: 10000 | DW13: 10000 | DX13: 10000 | DY13: 10000 | DZ13: 10000 | EA13: 10000 | EB13: 10000 | EC13: 10000 | ED13: 10000 | EE13: 5820 | EF13: 4092 | EG13: 3743 | EH13: 3441 | EI13: 3463 | EJ13: 3440 | EK13: 3393 | EL13: 3200 | EM13: 2999 | EN13: 2980 | EO13: 2781 | EP13: 2760 | EQ13: 2661 | ER13: 2660 | ES13: 2660 | ET13: 2660 | EU13: 2612 | EV13: 2612 | EW13: 2688 | EX13: 2850 | EY13: 3049 | EZ13: 3302 | FA13: 3491 | FB13: 3710 | FC13: 4091 | FD13: 5499 | FE13: 7501 | FF13: 10000 | FG13: 10000 | FH13: 10000 | FI13: 10000 | FJ13: 10000 | FK13: 10000 | FL13: 10000 | FM13: 10000 | FN13: 10000 | FO13: 10000 | FP13: 10000 | FQ13: 10000 | FR13: 10000 | FS13: 10000 | FT13: 10000 | FU13: 10000 | FV13: 10000 | FW13: 10000 | FX13: 10000 | FY13: 10000 | FZ13: 10000 | GA13: 10000 | GB13: 10000 | GC13: 10000 | GD13: 10000 | GE13: 10000 | GF13: 10000 | GG13: 10000 | GH13: 10000 | GI13: 10000 | GJ13: 10000 | GK13: 10000 | GL13: 10000
A14: DAM | B14: 11 | C14: 10000 | D14: 10000 | E14: 10000 | F14: 10000 | G14: 10000 | H14: 10000 | I14: 10000 | J14: 10000 | K14: 10000 | L14: 10000 | M14: 10000 | N14: 10000 | O14: 10000 | P14: 10000 | Q14: 10000 | R14: 10000 | S14: 10000 | T14: 10000 | U14: 10000 | V14: 10000 | W14: 10000 | X14: 10000 | Y14: 10000 | Z14: 10000 | AA14: 10000 | AB14: 10000 | AC14: 10000 | AD14: 10000 | AE14: 10000 | AF14: 10000 | AG14: 10000 | AH14: 10000 | AI14: 10000 | AJ14: 10000 | AK14: 10000 | AL14: 5820 | AM14: 4901 | AN14: 4104 | AO14: 3743 | AP14: 3603 | AQ14: 3648 | AR14: 3547 | AS14: 3545 | AT14: 3500 | AU14: 3501 | AV14: 3466 | AW14: 3466 | AX14: 3459 | AY14: 3207 | AZ14: 3201 | BA14: 3240 | BB14: 3200 | BC14: 2989 | BD14: 3002 | BE14: 3131 | BF14: 3300 | BG14: 3528 | BH14: 3560 | BI14: 3824 | BJ14: 4000 | BK14: 4750 | BL14: 5512 | BM14: 9000 | BN14: 10000 | BO14: 10000 | BP14: 10000 | BQ14: 10000 | BR14: 10000 | BS14: 10000 | BT14: 10000 | BU14: 10000 | BV14: 10000 | BW14: 10000 | BX14: 10000 | BY14: 10000 | BZ14: 10000 | CA14: 10000 | CB14: 10000 | CC14: 10000 | CD14: 10000 | CE14: 10000 | CF14: 10000 | CG14: 10000 | CH14: 10000 | CI14: 10000 | CJ14: 10000 | CK14: 10000 | CL14: 10000 | CM14: 10000 | CN14: 10000 | CO14: 10000 | CP14: 10000 | CQ14: 10000 | CR14: 10000 | CS14: 10000 | CT14: 10000 | CU14: 10000 | CV14: 10000 | CW14: 10000 | CX14: 10000 | CY14: 10000 | CZ14: 10000 | DA14: 10000 | DB14: 10000 | DC14: 10000 | DD14: 10000 | DE14: 10000 | DF14: 10000 | DG14: 10000 | DH14: 10000 | DI14: 10000 | DJ14: 10000 | DK14: 10000 | DL14: 10000 | DM14: 10000 | DN14: 10000 | DO14: 10000 | DP14: 10000 | DQ14: 10000 | DR14: 10000 | DS14: 10000 | DT14: 10000 | DU14: 10000 | DV14: 10000 | DW14: 10000 | DX14: 10000 | DY14: 10000 | DZ14: 10000 | EA14: 10000 | EB14: 10000 | EC14: 10000 | ED14: 5820 | EE14: 4901 | EF14: 4104 | EG14: 3743 | EH14: 3603 | EI14: 3648 | EJ14: 3547 | EK14: 3545 | EL14: 3500 | EM14: 3501 | EN14: 3466 | EO14: 3466 | EP14: 3459 | EQ14: 3207 | ER14: 3201 | ES14: 3240 | ET14: 3200 | EU14: 2989 | EV14: 3002 | EW14: 3131 | EX14: 3300 | EY14: 3528 | EZ14: 3560 | FA14: 3824 | FB14: 4000 | FC14: 4750 | FD14: 5512 | FE14: 9000 | FF14: 10000 | FG14: 10000 | FH14: 10000 | FI14: 10000 | FJ14: 10000 | FK14: 10000 | FL14: 10000 | FM14: 10000 | FN14: 10000 | FO14: 10000 | FP14: 10000 | FQ14: 10000 | FR14: 10000 | FS14: 10000 | FT14: 10000 | FU14: 10000 | FV14: 10000 | FW14: 10000 | FX14: 10000 | FY14: 10000 | FZ14: 10000 | GA14: 10000 | GB14: 10000 | GC14: 10000 | GD14: 10000 | GE14: 10000 | GF14: 10000 | GG14: 10000 | GH14: 10000 | GI14: 10000 | GJ14: 10000 | GK14: 10000 | GL14: 10000
A15: DAM | B15: 12 | C15: 10000 | D15: 10000 | E15: 10000 | F15: 10000 | G15: 10000 | H15: 10000 | I15: 10000 | J15: 10000 | K15: 10000 | L15: 10000 | M15: 10000 | N15: 10000 | O15: 10000 | P15: 10000 | Q15: 10000 | R15: 10000 | S15: 10000 | T15: 10000 | U15: 10000 | V15: 10000 | W15: 10000 | X15: 10000 | Y15: 10000 | Z15: 10000 | AA15: 10000 | AB15: 10000 | AC15: 10000 | AD15: 10000 | AE15: 10000 | AF15: 10000 | AG15: 10000 | AH15: 10000 | AI15: 10000 | AJ15: 10000 | AK15: 10000 | AL15: 10000 | AM15: 6454 | AN15: 4990 | AO15: 3743 | AP15: 3561 | AQ15: 3545 | AR15: 3402 | AS15: 3401 | AT15: 3258 | AU15: 3180 | AV15: 3180 | AW15: 3103 | AX15: 3051 | AY15: 3048 | AZ15: 3180 | BA15: 3050 | BB15: 3049 | BC15: 2711 | BD15: 2711 | BE15: 2999 | BF15: 3199 | BG15: 3528 | BH15: 3561 | BI15: 3747 | BJ15: 4299 | BK15: 9002 | BL15: 10000 | BM15: 10000 | BN15: 10000 | BO15: 10000 | BP15: 10000 | BQ15: 10000 | BR15: 10000 | BS15: 10000 | BT15: 10000 | BU15: 10000 | BV15: 10000 | BW15: 10000 | BX15: 10000 | BY15: 10000 | BZ15: 10000 | CA15: 10000 | CB15: 10000 | CC15: 10000 | CD15: 10000 | CE15: 10000 | CF15: 10000 | CG15: 10000 | CH15: 10000 | CI15: 10000 | CJ15: 10000 | CK15: 10000 | CL15: 10000 | CM15: 10000 | CN15: 10000 | CO15: 10000 | CP15: 10000 | CQ15: 10000 | CR15: 10000 | CS15: 10000 | CT15: 10000 | CU15: 10000 | CV15: 10000 | CW15: 10000 | CX15: 10000 | CY15: 10000 | CZ15: 10000 | DA15: 10000 | DB15: 10000 | DC15: 10000 | DD15: 10000 | DE15: 10000 | DF15: 10000 | DG15: 10000 | DH15: 10000 | DI15: 10000 | DJ15: 10000 | DK15: 10000 | DL15: 10000 | DM15: 10000 | DN15: 10000 | DO15: 10000 | DP15: 10000 | DQ15: 10000 | DR15: 10000 | DS15: 10000 | DT15: 10000 | DU15: 10000 | DV15: 10000 | DW15: 10000 | DX15: 10000 | DY15: 10000 | DZ15: 10000 | EA15: 10000 | EB15: 10000 | EC15: 10000 | ED15: 10000 | EE15: 6454 | EF15: 4990 | EG15: 3743 | EH15: 3561 | EI15: 3545 | EJ15: 3402 | EK15: 3401 | EL15: 3258 | EM15: 3180 | EN15: 3180 | EO15: 3103 | EP15: 3051 | EQ15: 3048 | ER15: 3180 | ES15: 3050 | ET15: 3049 | EU15: 2711 | EV15: 2711 | EW15: 2999 | EX15: 3199 | EY15: 3528 | EZ15: 3561 | FA15: 3747 | FB15: 4299 | FC15: 9002 | FD15: 10000 | FE15: 10000 | FF15: 10000 | FG15: 10000 | FH15: 10000 | FI15: 10000 | FJ15: 10000 | FK15: 10000 | FL15: 10000 | FM15: 10000 | FN15: 10000 | FO15: 10000 | FP15: 10000 | FQ15: 10000 | FR15: 10000 | FS15: 10000 | FT15: 10000 | FU15: 10000 | FV15: 10000 | FW15: 10000 | FX15: 10000 | FY15: 10000 | FZ15: 10000 | GA15: 10000 | GB15: 10000 | GC15: 10000 | GD15: 10000 | GE15: 10000 | GF15: 10000 | GG15: 10000 | GH15: 10000 | GI15: 10000 | GJ15: 10000 | GK15: 10000 | GL15: 10000
... A93: RTM | B93: 30 | C93: 5393 | D93: 5064 | E93: 4827 | F93: 4654 | G93: 4036 | H93: 3830 | I93: 4001 | J93: 3830 | K93: 3409 | L93: 3271 | M93: 3391 | N93: 3501 | O93: 3390 | P93: 3404 | Q93: 3501 | R93: 3409 | S93: 3270 | T93: 3304 | U93: 3410 | V93: 3410 | W93: 3611 | X93: 3630 | Y93: 3612 | Z93: 3541 | AA93: 3410 | AB93: 3946 | AC93: 3839 | AD93: 3611 | AE93: 3303 | AF93: 3000 | AG93: 2767 | AH93: 2499 | AI93: 2169 | AJ93: 2082 | AK93: 2369 | AL93: 2396 | AM93: 2803 | AN93: 2517 | AO93: 2938 | AP93: 2899 | AQ93: 3197 | AR93: 3166 | AS93: 2850 | AT93: 2550 | AU93: 2136 | AV93: 2081 | AW93: 2219 | AX93: 2268 | AY93: 2396 | AZ93: 2550 | BA93: 2371 | BB93: 2368 | BC93: 2135 | BD93: 2169 | BE93: 2101 | BF93: 2269 | BG93: 2371 | BH93: 2751 | BI93: 3117 | BJ93: 3067 | BK93: 2700 | BL93: 2811 | BM93: 3010 | BN93: 3081 | BO93: 2460 | BP93: 2632 | BQ93: 2781 | BR93: 3196 | BS93: 2970 | BT93: 3410 | BU93: 3630 | BV93: 4006 | BW93: 2781 | BX93: 3256 | BY93: 4853 | BZ93: 4600 | CA93: 5393 | CB93: 5379 | CC93: 4900 | CD93: 3761 | CE93: 3559 | CF93: 3582 | CG93: 2699 | CH93: 3506 | CI93: 2880 | CJ93: 3270 | CK93: 2013 | CL93: 2780 | CM93: 3116 | CN93: 3196 | CO93: 3321 | CP93: 3409 | CQ93: 3116 | CR93: 2646 | CS93: 2699 | CT93: 2550 | CU93: 5393 | CV93: 5064 | CW93: 4827 | CX93: 4654 | CY93: 4036 | CZ93: 3830 | DA93: 4001 | DB93: 3830 | DC93: 3409 | DD93: 3271 | DE93: 3391 | DF93: 3501 | DG93: 3390 | DH93: 3404 | DI93: 3501 | DJ93: 3409 | DK93: 3270 | DL93: 3304 | DM93: 3410 | DN93: 3410 | DO93: 3611 | DP93: 3630 | DQ93: 3612 | DR93: 3541 | DS93: 3410 | DT93: 3946 | DU93: 3839 | DV93: 3611 | DW93: 3303 | DX93: 3000 | DY93: 2767 | DZ93: 2499 | EA93: 2169 | EB93: 2082 | EC93: 2369 | ED93: 2396 | EE93: 2803 | EF93: 2517 | EG93: 2938 | EH93: 2899 | EI93: 3197 | EJ93: 3166 | EK93: 2850 | EL93: 2550 | EM93: 2136 | EN93: 2081 | EO93: 2219 | EP93: 2268 | EQ93: 2396 | ER93: 2550 | ES93: 2371 | ET93: 2368 | EU93: 2135 | EV93: 2169 | EW93: 2101 | EX93: 2269 | EY93: 2371 | EZ93: 2751 | FA93: 3117 | FB93: 3067 | FC93: 2700 | FD93: 2811 | FE93: 3010 | FF93: 3081 | FG93: 2460 | FH93: 2632 | FI93: 2781 | FJ93: 3196 | FK93: 2970 | FL93: 3410 | FM93: 3630 | FN93: 4006 | FO93: 2781 | FP93: 3256 | FQ93: 4853 | FR93: 4600 | FS93: 5393 | FT93: 5379 | FU93: 4900 | FV93: 3761 | FW93: 3559 | FX93: 3582 | FY93: 2699 | FZ93: 3506 | GA93: 2880 | GB93: 3270 | GC93: 2013 | GD93: 2780 | GE93: 3116 | GF93: 3196 | GG93: 3321 | GH93: 3409 | GI93: 3116 | GJ93: 2646 | GK93: 2699 | GL93: 2550

Sheet SolarProfile
A1: Solar output per MWac by plant, month and 15-minute block
A2: From the HTML model: clipped daylight curve for each plant's latitude, scaled to the stated CUF (30%) with a monthly irradiance shape. Multiply by the plant MWac. Re-export (or use the app's Generate button) if CUF changes.
A3: Plant|month | B3: Block → | C3: 0 | D3: 1 | E3: 2 | F3: 3 | G3: 4 | H3: 5 | I3: 6 | J3: 7 | K3: 8 | L3: 9 | M3: 10 | N3: 11 | O3: 12 | P3: 13 | Q3: 14 | R3: 15 | S3: 16 | T3: 17 | U3: 18 | V3: 19 | W3: 20 | X3: 21 | Y3: 22 | Z3: 23 | AA3: 24 | AB3: 25 | AC3: 26 | AD3: 27 | AE3: 28 | AF3: 29 | AG3: 30 | AH3: 31 | AI3: 32 | AJ3: 33 | AK3: 34 | AL3: 35 | AM3: 36 | AN3: 37 | AO3: 38 | AP3: 39 | AQ3: 40 | AR3: 41 | AS3: 42 | AT3: 43 | AU3: 44 | AV3: 45 | AW3: 46 | AX3: 47 | AY3: 48 | AZ3: 49 | BA3: 50 | BB3: 51 | BC3: 52 | BD3: 53 | BE3: 54 | BF3: 55 | BG3: 56 | BH3: 57 | BI3: 58 | BJ3: 59 | BK3: 60 | BL3: 61 | BM3: 62 | BN3: 63 | BO3: 64 | BP3: 65 | BQ3: 66 | BR3: 67 | BS3: 68 | BT3: 69 | BU3: 70 | BV3: 71 | BW3: 72 | BX3: 73 | BY3: 74 | BZ3: 75 | CA3: 76 | CB3: 77 | CC3: 78 | CD3: 79 | CE3: 80 | CF3: 81 | CG3: 82 | CH3: 83 | CI3: 84 | CJ3: 85 | CK3: 86 | CL3: 87 | CM3: 88 | CN3: 89 | CO3: 90 | CP3: 91 | CQ3: 92 | CR3: 93 | CS3: 94 | CT3: 95
A4: P7|1 | B4: Jan | C4: 0 | D4: 0 | E4: 0 | F4: 0 | G4: 0 | H4: 0 | I4: 0 | J4: 0 | K4: 0 | L4: 0 | M4: 0 | N4: 0 | O4: 0 | P4: 0 | Q4: 0 | R4: 0 | S4: 0 | T4: 0 | U4: 0 | V4: 0 | W4: 0 | X4: 0 | Y4: 0 | Z4: 0 | AA4: 0 | AB4: 0 | AC4: 0.001483 | AD4: 0.041399 | AE4: 0.099188 | AF4: 0.16711 | AG4: 0.24202 | AH4: 0.321846 | AI4: 0.40497 | AJ4: 0.490013 | AK4: 0.575741 | AL4: 0.661025 | AM4: 0.744816 | AN4: 0.826132 | AO4: 0.904059 | AP4: 0.977746 | AQ4: 1 | AR4: 1 | AS4: 1 | AT4: 1 | AU4: 1 | AV4: 1 | AW4: 1 | AX4: 1 | AY4: 1 | AZ4: 1 | BA4: 1 | BB4: 1 | BC4: 1 | BD4: 1 | BE4: 1 | BF4: 1 | BG4: 1 | BH4: 1 | BI4: 0.977746 | BJ4: 0.904059 | BK4: 0.826132 | BL4: 0.744816 | BM4: 0.661025 | BN4: 0.575741 | BO4: 0.490013 | BP4: 0.40497 | BQ4: 0.321846 | BR4: 0.24202 | BS4: 0.16711 | BT4: 0.099188 | BU4: 0.041399 | BV4: 0.001483 | BW4: 0 | BX4: 0 | BY4: 0 | BZ4: 0 | CA4: 0 | CB4: 0 | CC4: 0 | CD4: 0 | CE4: 0 | CF4: 0 | CG4: 0 | CH4: 0 | CI4: 0 | CJ4: 0 | CK4: 0 | CL4: 0 | CM4: 0 | CN4: 0 | CO4: 0 | CP4: 0 | CQ4: 0 | CR4: 0 | CS4: 0 | CT4: 0
A5: P7|2 | B5: Feb | C5: 0 | D5: 0 | E5: 0 | F5: 0 | G5: 0 | H5: 0 | I5: 0 | J5: 0 | K5: 0 | L5: 0 | M5: 0 | N5: 0 | O5: 0 | P5: 0 | Q5: 0 | R5: 0 | S5: 0 | T5: 0 | U5: 0 | V5: 0 | W5: 0 | X5: 0 | Y5: 0 | Z5: 0 | AA5: 0 | AB5: 0 | AC5: 0.021382 | AD5: 0.076614 | AE5: 0.145338 | AF5: 0.222976 | AG5: 0.306936 | AH5: 0.395326 | AI5: 0.48659 | AJ5: 0.579369 | AK5: 0.67243 | AL5: 0.764632 | AM5: 0.854915 | AN5: 0.942283 | AO5: 1 | AP5: 1 | AQ5: 1 | AR5: 1 | AS5: 1 | AT5: 1 | AU5: 1 | AV5: 1 | AW5: 1 | AX5: 1 | AY5: 1 | AZ5: 1 | BA5: 1 | BB5: 1 | BC5: 1 | BD5: 1 | BE5: 1 | BF5: 1 | BG5: 1 | BH5: 1 | BI5: 1 | BJ5: 1 | BK5: 0.942283 | BL5: 0.854915 | BM5: 0.764632 | BN5: 0.67243 | BO5: 0.579369 | BP5: 0.48659 | BQ5: 0.395326 | BR5: 0.306936 | BS5: 0.222976 | BT5: 0.145338 | BU5: 0.076614 | BV5: 0.021382 | BW5: 0 | BX5: 0 | BY5: 0 | BZ5: 0 | CA5: 0 | CB5: 0 | CC5: 0 | CD5: 0 | CE5: 0 | CF5: 0 | CG5: 0 | CH5: 0 | CI5: 0 | CJ5: 0 | CK5: 0 | CL5: 0 | CM5: 0 | CN5: 0 | CO5: 0 | CP5: 0 | CQ5: 0 | CR5: 0 | CS5: 0 | CT5: 0
